<?xml version="1.0"?>
<robot xmlns:xacro="http://www.ros.org/wiki/xacro">

    <xacro:property name="mass_base" value="1.0" />
    <xacro:property name="mass_upper" value="0.250" />

    <link name="world" />

    <link name="base_link">
        <visual>
            <origin xyz="-0.1 -0.1 0" rpy="0 0 0" />
            <geometry>
                <mesh filename="package://protobot_description/meshes/base.STL"
                    scale="0.001 0.001 0.001" />
            </geometry>
            <material name="orange" />
        </visual>
        <collision>
            <origin xyz="-0.1 -0.1 0" rpy="0 0 0" />
            <geometry>
                <mesh filename="package://protobot_description/meshes/base.STL"
                    scale="0.001 0.001 0.001" />
            </geometry>
        </collision>
        <inertial>
            <mass value="${mass_base}" />
            <inertia ixx="0.352441" ixy="0" ixz="0"
                iyy="0.352441" iyz="0"
                izz="0.703125" />
        </inertial>
    </link>

    <link name="upper_link">
        <visual>
            <origin xyz="0.055 -0.025 0.23" rpy="${pi} 0 ${pi}" />
            <geometry>
                <mesh filename="package://protobot_description/meshes/upper.STL"
                    scale="0.001 0.001 0.001" />
            </geometry>
            <material name="green" />
        </visual>
        <collision>
            <origin xyz="0.055 -0.025 0.23" rpy="${pi} 0 ${pi}" />
            <geometry>
                <mesh filename="package://protobot_description/meshes/upper.STL"
                    scale="0.001 0.001 0.001" />
            </geometry>
        </collision>
        <inertial>
            <mass value="${mass_upper}" />
            <inertia ixx="0.227504" ixy="0" ixz="0"
                iyy="0.023582" iyz="0.006557"
                izz="0.249198" />
        </inertial>
    </link>

    <joint name="world_base_joint" type="fixed">
        <origin xyz="0 0 0" rpy="0 0 0" />
        <parent link="world" />
        <child link="base_link" />
    </joint>

    <joint name="shoulder_joint" type="revolute">
        <origin xyz="0.03 0 0.28" rpy="0 0 0" />
        <parent link="base_link" />
        <child link="upper_link" />
        <axis xyz="1 0 0" />
        <limit lower="-${(3*pi)/4}" upper="${(3*pi)/4}" effort="10" velocity="1" />
    </joint>

</robot>